<?xml version="1.0" encoding="utf-8"?>
<!-- This URDF was automatically created by SolidWorks to URDF Exporter! Originally created by Stephen Brawner (brawner@gmail.com) 
     Commit Version: 1.6.0-4-g7f85cfe  Build Version: 1.6.7995.38578
     For more information, please see http://wiki.ros.org/sw_urdf_exporter -->
<robot
  name="urdf_assembly3">
  <link name="world"/>
<joint name="base_joint" type="fixed">
<parent link="world"/>
<child link="base_link"/>
<origin rpy="0 0 0" xyz="0.0 0.0 0.17"/>
</joint>

  <link
    name="base_link">
    <inertial>
      <origin
        xyz="2.387E-15 -0.18027 -0.045837"
        rpy="0 0 0" />
      <mass
        value="0.90639" />
      <inertia
        ixx="0.021934"
        ixy="-4.7325E-17"
        ixz="-4.2054E-18"
        iyy="0.021934"
        iyz="3.2779E-17"
        izz="0.043368" />
    </inertial>
    <visual>
      <origin
        xyz="0 0 0"
        rpy="0 0 0" />
      <geometry>
        <mesh
          filename="package://urdf_assembly3/meshes/base_link.STL" />
      </geometry>
      <material
        name="">
        <color
          rgba="0.79216 0.81961 0.93333 1" />
      </material>
    </visual>
    <collision>
      <origin
        xyz="0 0 0"
        rpy="0 0 0" />
      <geometry>
        <mesh
          filename="package://urdf_assembly3/meshes/base_link.STL" />
      </geometry>
    </collision>
  </link>
  <link
    name="link_1">
    <inertial>
      <origin
        xyz="-0.013312 0.00078157 0.041458"
        rpy="0 0 0" />
      <mass
        value="0.70484" />
      <inertia
        ixx="0.0010961"
        ixy="-3.8544E-05"
        ixz="8.1564E-05"
        iyy="0.00080176"
        iyz="3.4049E-05"
        izz="0.00072923" />
    </inertial>
    <visual>
      <origin
        xyz="0 0 0"
        rpy="0 0 0" />
      <geometry>
        <mesh
          filename="package://urdf_assembly3/meshes/link_1.STL" />
      </geometry>
      <material
        name="">
        <color
          rgba="0.79216 0.81961 0.93333 1" />
      </material>
    </visual>
    <collision>
      <origin
        xyz="0 0 0"
        rpy="0 0 0" />
      <geometry>
        <mesh
          filename="package://urdf_assembly3/meshes/link_1.STL" />
      </geometry>
    </collision>
  </link>
  <joint
    name="joint_1"
    type="fixed">
    <origin
      xyz="0 0 0"
      rpy="0 0 0" />
    <parent
      link="base_link" />
    <child
      link="link_1" />
    <axis
      xyz="0 0 0" />
  </joint>
  <link
    name="link_2">
    <inertial>
      <origin
        xyz="0.17364 0.00070136 0.025562"
        rpy="0 0 0" />
      <mass
        value="0.57902" />
      <inertia
        ixx="0.00028798"
        ixy="-2.5377E-05"
        ixz="-3.659E-05"
        iyy="0.0065707"
        iyz="-1.4779E-07"
        izz="0.0067196" />
    </inertial>
    <visual>
      <origin
        xyz="0 0 0"
        rpy="0 0 0" />
      <geometry>
        <mesh
          filename="package://urdf_assembly3/meshes/link_2.STL" />
      </geometry>
      <material
        name="">
        <color
          rgba="0.79216 0.81961 0.93333 1" />
      </material>
    </visual>
    <collision>
      <origin
        xyz="0 0 0"
        rpy="0 0 0" />
      <geometry>
        <mesh
          filename="package://urdf_assembly3/meshes/link_2.STL" />
      </geometry>
    </collision>
  </link>
  <joint
    name="joint_2"
    type="revolute">
    <origin
      xyz="0.012 -0.0040048 0.112"
      rpy="0 -1.5708 3.1416" />
    <parent
      link="link_1" />
    <child
      link="link_2" />
    <axis
      xyz="0 0 1" />
    <limit
      lower="-1"
      upper="1.5"
      effort="0.7"
      velocity="0.5" />
  </joint>
  <link
    name="link_3">
    <inertial>
      <origin
        xyz="0.17364 -0.0018544 0.025562"
        rpy="0 0 0" />
      <mass
        value="0.57902" />
      <inertia
        ixx="0.0002886"
        ixy="6.7091E-05"
        ixz="-3.6589E-05"
        iyy="0.0065701"
        iyz="3.9075E-07"
        izz="0.0067196" />
    </inertial>
    <visual>
      <origin
        xyz="0 0 0"
        rpy="0 0 0" />
      <geometry>
        <mesh
          filename="package://urdf_assembly3/meshes/link_3.STL" />
      </geometry>
      <material
        name="">
        <color
          rgba="0.79216 0.81961 0.93333 1" />
      </material>
    </visual>
    <collision>
      <origin
        xyz="0 0 0"
        rpy="0 0 0" />
      <geometry>
        <mesh
          filename="package://urdf_assembly3/meshes/link_3.STL" />
      </geometry>
    </collision>
  </link>
  <joint
    name="joint_3"
    type="revolute">
    <origin
      xyz="0.3 0.0012117 -0.004"
      rpy="3.1416 0 0" />
    <parent
      link="link_2" />
    <child
      link="link_3" />
    <axis
      xyz="0 0 1" />
    <limit
      lower="-1"
      upper="1.5"
      effort="0.7"
      velocity="0.5" />
  </joint>
  <link
    name="link_4">
    <inertial>
      <origin
        xyz="0.094221 -0.0079481 0.019986"
        rpy="0 0 0" />
      <mass
        value="0.12035" />
      <inertia
        ixx="1.8013E-05"
        ixy="1.5046E-05"
        ixz="-5.6387E-19"
        iyy="0.00053115"
        iyz="3.0882E-21"
        izz="0.00052647" />
    </inertial>
    <visual>
      <origin
        xyz="0 0 0"
        rpy="0 0 0" />
      <geometry>
        <mesh
          filename="package://urdf_assembly3/meshes/link_4.STL" />
      </geometry>
      <material
        name="">
        <color
          rgba="0.79216 0.81961 0.93333 1" />
      </material>
    </visual>
    <collision>
      <origin
        xyz="0 0 0"
        rpy="0 0 0" />
      <geometry>
        <mesh
          filename="package://urdf_assembly3/meshes/link_4.STL" />
      </geometry>
    </collision>
  </link>
  <joint
    name="joint_4"
    type="revolute">
    <origin
      xyz="0.29998 -0.0032037 -0.004"
      rpy="-3.1416 0 0" />
    <parent
      link="link_3" />
    <child
      link="link_4" />
    <axis
      xyz="0 0 -1" />
    <limit
      lower="-1"
      upper="1.5"
      effort="0.7"
      velocity="0.5" />
  </joint>
  <transmission name="link_1_trans">
<type>transmission_interface/SimpleTransmission</type>
<joint name="joint_1">
<hardwareInterface>hardware_interface/PositionJointInterface</hardwareInterface>
</joint>
<actuator name="link_1_motor">
<hardwareInterface>hardware_interface/PositionJointInterface</hardwareInterface>
<mechanicalReduction>1</mechanicalReduction>
</actuator>
</transmission>

<transmission name="link_2_trans">
<type>transmission_interface/SimpleTransmission</type>
<joint name="joint_2">
<hardwareInterface>hardware_interface/PositionJointInterface</hardwareInterface>
</joint>
<actuator name="link_2_motor">
<hardwareInterface>hardware_interface/PositionJointInterface</hardwareInterface>
<mechanicalReduction>1</mechanicalReduction>
</actuator>
</transmission>

<transmission name="link_3_trans">
<type>transmission_interface/SimpleTransmission</type>
<joint name="joint_3">
<hardwareInterface>hardware_interface/PositionJointInterface</hardwareInterface>
</joint>
<actuator name="link_3_motor">
<hardwareInterface>hardware_interface/PositionJointInterface</hardwareInterface>
<mechanicalReduction>1</mechanicalReduction>
</actuator>
</transmission>

<transmission name="link_4_trans">
<type>transmission_interface/SimpleTransmission</type>
<joint name="joint_4">
<hardwareInterface>hardware_interface/PositionJointInterface</hardwareInterface>
</joint>
<actuator name="link_4_motor">
<hardwareInterface>hardware_interface/PositionJointInterface</hardwareInterface>
<mechanicalReduction>1</mechanicalReduction>
</actuator>
</transmission>

<gazebo>
<plugin name="control"
filename="libgazebo_ros_control.so">
<robotNamespace>/</robotNamespace>
</plugin>
</gazebo>

<gazebo reference="link_1">
<selfCollide>true</selfCollide>
</gazebo>
v
<gazebo reference="link_2">
<selfCollide>true</selfCollide>
</gazebo>
<gazebo reference="link_3">
<selfCollide>true</selfCollide>
</gazebo>
<gazebo reference="link_4">
<selfCollide>true</selfCollide>
</gazebo>
</robot>
